2023-12-26 ｜ 11:36:15
2023-12-26 ｜ 11:36:17 ========================[ERROR]=======================
Traceback (most recent call last):
Traceback (most recent call last):
  File "/Users/kumo/Tomorin_v2/git/TomorinBot/core/app.py", line 19, in <module>
    2023-12-26 ｜ 11:36:17 ========================[END]=======================

KeyboardInterrupt
2023-12-26 ｜ 13:10:06
Exception in thread Thread-60 (_help_action):
2023-12-26 ｜ 13:10:38 ========================[ERROR]=======================
Traceback (most recent call last):
Traceback (most recent call last):
  File "/Library/Frameworks/Python.framework/Versions/3.12/lib/python3.12/threading.py", line 1073, in _bootstrap_inner
    self.run()
  File "/Library/Frameworks/Python.framework/Versions/3.12/lib/python3.12/threading.py", line 1010, in run
    self._target(*self._args, **self._kwargs)
  File "/Users/kumo/Tomorin_v2/git/TomorinBot/core/on.py", line 15, in inner_wrapper
    return func(event)
           ^^^^^^^^^^^
  File "/Users/kumo/Tomorin_v2/git/TomorinBot/plugins/help/__init__.py", line 9, in _help_action
    action.cutshort(cutshort=['help'], function=_help_do)
  File "/Users/kumo/Tomorin_v2/git/TomorinBot/plugins/action/__init__.py", line 39, in cutshort
    self._call(function)
  File "/Users/kumo/Tomorin_v2/git/TomorinBot/plugins/action/__init__.py", line 83, in _call
    function(self)
  File "/Users/kumo/Tomorin_v2/git/TomorinBot/plugins/help/__init__.py", line 17, in _help_do
    action.send(help_str)
  File "/Users/kumo/Tomorin_v2/git/TomorinBot/plugins/action/__init__.py", line 71, in send
    return self.event.message_create(channel_id=self.event.channel.id, content=message_content)
           ^^^^^^^^^^^^^^^^^^^^^^^^^^^^^^^^^^^^^^^^^^^^^^^^^^^^^^^^^^^^^^^^^^^^^^^^^^^^^^^^^^^^
  File "/Users/kumo/Tomorin_v2/git/TomorinBot/core/event.py", line 129, in message_create
    return send_request(event=self, method='message.create', data={
           ^^^^^^^^^^^^^^^^^^^^^^^^^^^^^^^^^^^^^^^^^^^^^^^^^^^^^^^^
  File "/Users/kumo/Tomorin_v2/git/TomorinBot/core/request.py", line 54, in send_request
    event, method, data, platform, self_id = v(event, method, data, platform, self_id)
                                             ^^^^^^^^^^^^^^^^^^^^^^^^^^^^^^^^^^^^^^^^^
  File "/Users/kumo/Tomorin_v2/git/TomorinBot/core/on.py", line 311, in wrapper
    return func(*args, **kwargs)
           ^^^^^^^^^^^^^^^^^^^^^
TypeError: _() takes 4 positional arguments but 5 were given
2023-12-26 ｜ 13:12:05 ========================[ERROR]=======================
Traceback (most recent call last):
Traceback (most recent call last):
  File "/Users/kumo/Tomorin_v2/git/TomorinBot/core/app.py", line 19, in <module>
    2023-12-26 ｜ 13:12:05 ========================[END]=======================

KeyboardInterrupt
2023-12-26 ｜ 13:12:05
Exception in thread Thread-20 (_help_action):
2023-12-26 ｜ 13:12:16 ========================[ERROR]=======================
Traceback (most recent call last):
Traceback (most recent call last):
  File "/Library/Frameworks/Python.framework/Versions/3.12/lib/python3.12/threading.py", line 1073, in _bootstrap_inner
    self.run()
  File "/Library/Frameworks/Python.framework/Versions/3.12/lib/python3.12/threading.py", line 1010, in run
    self._target(*self._args, **self._kwargs)
  File "/Users/kumo/Tomorin_v2/git/TomorinBot/core/on.py", line 15, in inner_wrapper
    return func(event)
           ^^^^^^^^^^^
  File "/Users/kumo/Tomorin_v2/git/TomorinBot/plugins/help/__init__.py", line 9, in _help_action
    action.cutshort(cutshort=['help'], function=_help_do)
  File "/Users/kumo/Tomorin_v2/git/TomorinBot/plugins/action/__init__.py", line 39, in cutshort
    self._call(function)
  File "/Users/kumo/Tomorin_v2/git/TomorinBot/plugins/action/__init__.py", line 83, in _call
    function(self)
  File "/Users/kumo/Tomorin_v2/git/TomorinBot/plugins/help/__init__.py", line 17, in _help_do
    action.send(help_str)
  File "/Users/kumo/Tomorin_v2/git/TomorinBot/plugins/action/__init__.py", line 71, in send
    return self.event.message_create(channel_id=self.event.channel.id, content=message_content)
           ^^^^^^^^^^^^^^^^^^^^^^^^^^^^^^^^^^^^^^^^^^^^^^^^^^^^^^^^^^^^^^^^^^^^^^^^^^^^^^^^^^^^
  File "/Users/kumo/Tomorin_v2/git/TomorinBot/core/event.py", line 129, in message_create
    return send_request(event=self, method='message.create', data={
           ^^^^^^^^^^^^^^^^^^^^^^^^^^^^^^^^^^^^^^^^^^^^^^^^^^^^^^^^
  File "/Users/kumo/Tomorin_v2/git/TomorinBot/core/request.py", line 54, in send_request
    event, method, data, platform, self_id = v(event, method, data, platform, self_id)
                                             ^^^^^^^^^^^^^^^^^^^^^^^^^^^^^^^^^^^^^^^^^
  File "/Users/kumo/Tomorin_v2/git/TomorinBot/core/on.py", line 311, in wrapper
    return func(*args, **kwargs)
           ^^^^^^^^^^^^^^^^^^^^^
TypeError: _satori_post() takes 4 positional arguments but 5 were given
2023-12-26 ｜ 13:13:38 ========================[ERROR]=======================
Traceback (most recent call last):
Traceback (most recent call last):
  File "/Users/kumo/Tomorin_v2/git/TomorinBot/core/app.py", line 19, in <module>
    2023-12-26 ｜ 13:13:38 ========================[END]=======================

KeyboardInterrupt
2023-12-26 ｜ 13:13:38
Exception in thread Thread-15 (_help_action):
2023-12-26 ｜ 13:13:44 ========================[ERROR]=======================
Traceback (most recent call last):
Traceback (most recent call last):
  File "/Library/Frameworks/Python.framework/Versions/3.12/lib/python3.12/threading.py", line 1073, in _bootstrap_inner
    self.run()
  File "/Library/Frameworks/Python.framework/Versions/3.12/lib/python3.12/threading.py", line 1010, in run
    self._target(*self._args, **self._kwargs)
  File "/Users/kumo/Tomorin_v2/git/TomorinBot/core/on.py", line 15, in inner_wrapper
    return func(event)
           ^^^^^^^^^^^
  File "/Users/kumo/Tomorin_v2/git/TomorinBot/plugins/help/__init__.py", line 9, in _help_action
    action.cutshort(cutshort=['help'], function=_help_do)
  File "/Users/kumo/Tomorin_v2/git/TomorinBot/plugins/action/__init__.py", line 39, in cutshort
    self._call(function)
  File "/Users/kumo/Tomorin_v2/git/TomorinBot/plugins/action/__init__.py", line 83, in _call
    function(self)
  File "/Users/kumo/Tomorin_v2/git/TomorinBot/plugins/help/__init__.py", line 17, in _help_do
    action.send(help_str)
  File "/Users/kumo/Tomorin_v2/git/TomorinBot/plugins/action/__init__.py", line 71, in send
    return self.event.message_create(channel_id=self.event.channel.id, content=message_content)
           ^^^^^^^^^^^^^^^^^^^^^^^^^^^^^^^^^^^^^^^^^^^^^^^^^^^^^^^^^^^^^^^^^^^^^^^^^^^^^^^^^^^^
  File "/Users/kumo/Tomorin_v2/git/TomorinBot/core/event.py", line 129, in message_create
    return send_request(event=self, method='message.create', data={
           ^^^^^^^^^^^^^^^^^^^^^^^^^^^^^^^^^^^^^^^^^^^^^^^^^^^^^^^^
  File "/Users/kumo/Tomorin_v2/git/TomorinBot/core/request.py", line 54, in send_request
    event, method, data, platform, self_id = before_request_v(event, method, data, platform, self_id)
                                             ^^^^^^^^^^^^^^^^^^^^^^^^^^^^^^^^^^^^^^^^^^^^^^^^^^^^^^^^
  File "/Users/kumo/Tomorin_v2/git/TomorinBot/core/on.py", line 311, in wrapper
    return func(*args, **kwargs)
           ^^^^^^^^^^^^^^^^^^^^^
TypeError: _satori_post() takes 4 positional arguments but 5 were given
2023-12-26 ｜ 13:15:20 ========================[ERROR]=======================
Traceback (most recent call last):
Traceback (most recent call last):
  File "/Users/kumo/Tomorin_v2/git/TomorinBot/core/app.py", line 19, in <module>
    2023-12-26 ｜ 13:15:20 ========================[END]=======================

KeyboardInterrupt
2023-12-26 ｜ 13:15:21
Exception in thread Thread-10 (_help_action):
2023-12-26 ｜ 13:15:24 ========================[ERROR]=======================
Traceback (most recent call last):
Traceback (most recent call last):
  File "/Library/Frameworks/Python.framework/Versions/3.12/lib/python3.12/threading.py", line 1073, in _bootstrap_inner
    self.run()
  File "/Library/Frameworks/Python.framework/Versions/3.12/lib/python3.12/threading.py", line 1010, in run
    self._target(*self._args, **self._kwargs)
  File "/Users/kumo/Tomorin_v2/git/TomorinBot/core/on.py", line 15, in inner_wrapper
    return func(event)
           ^^^^^^^^^^^
  File "/Users/kumo/Tomorin_v2/git/TomorinBot/plugins/help/__init__.py", line 9, in _help_action
    action.cutshort(cutshort=['help'], function=_help_do)
  File "/Users/kumo/Tomorin_v2/git/TomorinBot/plugins/action/__init__.py", line 39, in cutshort
    self._call(function)
  File "/Users/kumo/Tomorin_v2/git/TomorinBot/plugins/action/__init__.py", line 83, in _call
    function(self)
  File "/Users/kumo/Tomorin_v2/git/TomorinBot/plugins/help/__init__.py", line 17, in _help_do
    action.send(help_str)
  File "/Users/kumo/Tomorin_v2/git/TomorinBot/plugins/action/__init__.py", line 71, in send
    return self.event.message_create(channel_id=self.event.channel.id, content=message_content)
           ^^^^^^^^^^^^^^^^^^^^^^^^^^^^^^^^^^^^^^^^^^^^^^^^^^^^^^^^^^^^^^^^^^^^^^^^^^^^^^^^^^^^
  File "/Users/kumo/Tomorin_v2/git/TomorinBot/core/event.py", line 129, in message_create
    return send_request(event=self, method='message.create', data={
           ^^^^^^^^^^^^^^^^^^^^^^^^^^^^^^^^^^^^^^^^^^^^^^^^^^^^^^^^
  File "/Users/kumo/Tomorin_v2/git/TomorinBot/core/request.py", line 55, in send_request
    event, method, data, platform, self_id = before_request_v(event, method, data, platform, self_id)
                                             ^^^^^^^^^^^^^^^^^^^^^^^^^^^^^^^^^^^^^^^^^^^^^^^^^^^^^^^^
  File "/Users/kumo/Tomorin_v2/git/TomorinBot/core/on.py", line 311, in wrapper
    return func(*args, **kwargs)
           ^^^^^^^^^^^^^^^^^^^^^
TypeError: _satori_post() takes 4 positional arguments but 5 were given
2023-12-26 ｜ 13:16:24 ========================[ERROR]=======================
Traceback (most recent call last):
Traceback (most recent call last):
  File "/Users/kumo/Tomorin_v2/git/TomorinBot/core/app.py", line 19, in <module>
    2023-12-26 ｜ 13:16:24 ========================[END]=======================

KeyboardInterrupt
2023-12-26 ｜ 13:16:25
Exception in thread Thread-15 (_help_action):
2023-12-26 ｜ 13:16:27 ========================[ERROR]=======================
Traceback (most recent call last):
Traceback (most recent call last):
  File "/Users/kumo/Tomorin_v2/git/TomorinBot/plugins/request/__init__.py", line 16, in _satori_post
    rep_dict = response_data['data']
               ~~~~~~~~~~~~~^^^^^^^^
TypeError: list indices must be integers or slices, not str

During handling of the above exception, another exception occurred:

2023-12-26 ｜ 13:16:27 ========================[ERROR]=======================
Traceback (most recent call last):
Traceback (most recent call last):
  File "/Library/Frameworks/Python.framework/Versions/3.12/lib/python3.12/threading.py", line 1073, in _bootstrap_inner
    self.run()
  File "/Library/Frameworks/Python.framework/Versions/3.12/lib/python3.12/threading.py", line 1010, in run
    self._target(*self._args, **self._kwargs)
  File "/Users/kumo/Tomorin_v2/git/TomorinBot/core/on.py", line 15, in inner_wrapper
    return func(event)
           ^^^^^^^^^^^
  File "/Users/kumo/Tomorin_v2/git/TomorinBot/plugins/help/__init__.py", line 9, in _help_action
    action.cutshort(cutshort=['help'], function=_help_do)
  File "/Users/kumo/Tomorin_v2/git/TomorinBot/plugins/action/__init__.py", line 39, in cutshort
    self._call(function)
  File "/Users/kumo/Tomorin_v2/git/TomorinBot/plugins/action/__init__.py", line 83, in _call
    function(self)
  File "/Users/kumo/Tomorin_v2/git/TomorinBot/plugins/help/__init__.py", line 17, in _help_do
    action.send(help_str)
  File "/Users/kumo/Tomorin_v2/git/TomorinBot/plugins/action/__init__.py", line 71, in send
    return self.event.message_create(channel_id=self.event.channel.id, content=message_content)
           ^^^^^^^^^^^^^^^^^^^^^^^^^^^^^^^^^^^^^^^^^^^^^^^^^^^^^^^^^^^^^^^^^^^^^^^^^^^^^^^^^^^^
  File "/Users/kumo/Tomorin_v2/git/TomorinBot/core/event.py", line 129, in message_create
    return send_request(event=self, method='message.create', data={
           ^^^^^^^^^^^^^^^^^^^^^^^^^^^^^^^^^^^^^^^^^^^^^^^^^^^^^^^^
  File "/Users/kumo/Tomorin_v2/git/TomorinBot/core/request.py", line 59, in send_request
    event, data, headers, full_address, response_dict = satori_post_v(event, data, headers, full_address)
                                                        ^^^^^^^^^^^^^^^^^^^^^^^^^^^^^^^^^^^^^^^^^^^^^^^^^
  File "/Users/kumo/Tomorin_v2/git/TomorinBot/core/on.py", line 311, in wrapper
    return func(*args, **kwargs)
           ^^^^^^^^^^^^^^^^^^^^^
  File "/Users/kumo/Tomorin_v2/git/TomorinBot/plugins/request/__init__.py", line 19, in _satori_post
    raise Exception(f'[core] 未能解析响应为JSON格式，响应：{response.text}')
Exception: [core] 未能解析响应为JSON格式，响应：[{"id":"7390984963144849501","elements":[{"type":"text","attrs":{"content":"当前可用的指令有：\n    猜谱面\n    没了\n发送 指令名 -h 可以查看指令的帮助～"},"children":[]}],"content":"当前可用的指令有：\n    猜谱面\n    没了\n发送 指令名 -h 可以查看指令的帮助～"}]
2023-12-26 ｜ 13:17:02 ========================[ERROR]=======================
Traceback (most recent call last):
Traceback (most recent call last):
  File "/Users/kumo/Tomorin_v2/git/TomorinBot/core/app.py", line 19, in <module>
    2023-12-26 ｜ 13:17:02 ========================[END]=======================

KeyboardInterrupt
2023-12-26 ｜ 13:17:02
Exception in thread Thread-10 (_help_action):
2023-12-26 ｜ 13:17:10 ========================[ERROR]=======================
Traceback (most recent call last):
Traceback (most recent call last):
  File "/Users/kumo/Tomorin_v2/git/TomorinBot/plugins/request/__init__.py", line 16, in _satori_post
    rep_dict = response_data.json()
               ^^^^^^^^^^^^^^^^^^
AttributeError: 'list' object has no attribute 'json'

During handling of the above exception, another exception occurred:

2023-12-26 ｜ 13:17:10 ========================[ERROR]=======================
Traceback (most recent call last):
Traceback (most recent call last):
  File "/Library/Frameworks/Python.framework/Versions/3.12/lib/python3.12/threading.py", line 1073, in _bootstrap_inner
    self.run()
  File "/Library/Frameworks/Python.framework/Versions/3.12/lib/python3.12/threading.py", line 1010, in run
    self._target(*self._args, **self._kwargs)
  File "/Users/kumo/Tomorin_v2/git/TomorinBot/core/on.py", line 15, in inner_wrapper
    return func(event)
           ^^^^^^^^^^^
  File "/Users/kumo/Tomorin_v2/git/TomorinBot/plugins/help/__init__.py", line 9, in _help_action
    action.cutshort(cutshort=['help'], function=_help_do)
  File "/Users/kumo/Tomorin_v2/git/TomorinBot/plugins/action/__init__.py", line 39, in cutshort
    self._call(function)
  File "/Users/kumo/Tomorin_v2/git/TomorinBot/plugins/action/__init__.py", line 83, in _call
    function(self)
  File "/Users/kumo/Tomorin_v2/git/TomorinBot/plugins/help/__init__.py", line 17, in _help_do
    action.send(help_str)
  File "/Users/kumo/Tomorin_v2/git/TomorinBot/plugins/action/__init__.py", line 71, in send
    return self.event.message_create(channel_id=self.event.channel.id, content=message_content)
           ^^^^^^^^^^^^^^^^^^^^^^^^^^^^^^^^^^^^^^^^^^^^^^^^^^^^^^^^^^^^^^^^^^^^^^^^^^^^^^^^^^^^
  File "/Users/kumo/Tomorin_v2/git/TomorinBot/core/event.py", line 129, in message_create
    return send_request(event=self, method='message.create', data={
           ^^^^^^^^^^^^^^^^^^^^^^^^^^^^^^^^^^^^^^^^^^^^^^^^^^^^^^^^
  File "/Users/kumo/Tomorin_v2/git/TomorinBot/core/request.py", line 59, in send_request
    event, data, headers, full_address, response_dict = satori_post_v(event, data, headers, full_address)
                                                        ^^^^^^^^^^^^^^^^^^^^^^^^^^^^^^^^^^^^^^^^^^^^^^^^^
  File "/Users/kumo/Tomorin_v2/git/TomorinBot/core/on.py", line 311, in wrapper
    return func(*args, **kwargs)
           ^^^^^^^^^^^^^^^^^^^^^
  File "/Users/kumo/Tomorin_v2/git/TomorinBot/plugins/request/__init__.py", line 19, in _satori_post
    raise Exception(f'[core] 未能解析响应为JSON格式，响应：{response.text}')
Exception: [core] 未能解析响应为JSON格式，响应：[{"id":"7390985147244750357","elements":[{"type":"text","attrs":{"content":"当前可用的指令有：\n    猜谱面\n    没了\n发送 指令名 -h 可以查看指令的帮助～"},"children":[]}],"content":"当前可用的指令有：\n    猜谱面\n    没了\n发送 指令名 -h 可以查看指令的帮助～"}]
2023-12-26 ｜ 13:17:45 ========================[ERROR]=======================
Traceback (most recent call last):
Traceback (most recent call last):
  File "/Users/kumo/Tomorin_v2/git/TomorinBot/core/app.py", line 19, in <module>
    2023-12-26 ｜ 13:17:45 ========================[END]=======================

KeyboardInterrupt
2023-12-26 ｜ 13:17:46
2023-12-26 ｜ 13:18:36 ========================[ERROR]=======================
Traceback (most recent call last):
Traceback (most recent call last):
  File "/Users/kumo/Tomorin_v2/git/TomorinBot/core/app.py", line 19, in <module>
    2023-12-26 ｜ 13:18:36 ========================[END]=======================

KeyboardInterrupt
2023-12-26 ｜ 13:18:54
2023-12-26 ｜ 13:20:50 ========================[ERROR]=======================
Traceback (most recent call last):
Traceback (most recent call last):
  File "/Users/kumo/Tomorin_v2/git/TomorinBot/core/app.py", line 19, in <module>
    2023-12-26 ｜ 13:20:50 ========================[END]=======================

KeyboardInterrupt
2023-12-26 ｜ 13:20:51
2023-12-26 ｜ 13:26:31 ========================[ERROR]=======================
Traceback (most recent call last):
Traceback (most recent call last):
  File "/Users/kumo/Tomorin_v2/git/TomorinBot/core/app.py", line 19, in <module>
    2023-12-26 ｜ 13:26:31 ========================[END]=======================

KeyboardInterrupt
2023-12-26 ｜ 13:26:34
2023-12-26 ｜ 13:26:36 ========================[ERROR]=======================
Traceback (most recent call last):
Traceback (most recent call last):
  File "/Users/kumo/Tomorin_v2/git/TomorinBot/core/app.py", line 19, in <module>
    2023-12-26 ｜ 13:26:36 ========================[END]=======================

KeyboardInterrupt
